Workbook

Sheet Liquidacion IVA
A2: PERIODO | B2: CREDITO | D2: PLANILLA | F2: DIFERENCIA
A3: 2023/04 | B3: 28581391 | D3: =+Facturas!F21 -> 28581387 | F3: =+B3-D3 -> 4.12
A4: 2023/05 | B4: 371481 | D4: =+Facturas!F40 -> 371480.97 | F4: =+B4-D4 -> 0.03
A5: 2023/06 | B5: =804156-15609+30671852 -> 31460399 | D5: =+Facturas!F85 -> 37701349 | F5: =+B5-D5 -> -6240950.4
A6: 2023/07 | B6: =2690212-65454+14067870 -> 16692628 | D6: =+Facturas!F129 -> 10451679 | F6: =+B6-D6 -> 6240949.3
A7: 2023/08 | B7: =635057+21085798 -> 21720855 | D7: =+Facturas!F160 -> 21720853 | F7: =+B7-D7 -> 1.9971
A8: 2023/09 | B8: =1549483-8112+2286704 -> 3828075 | D8: =+Facturas!F183 -> 3828072.8 | F8: =+B8-D8 -> 2.1863
A9: 2023/10 | B9: =12095793+2048376 -> 14144169 | D9: =+Facturas!F224 -> 14144168 | F9: =+B9-D9 -> 0.54300001
A10: 2023/11 | B10: 1176728 | D10: =+Facturas!F267 -> 4064811.9 | F10: =+B10-D10 -> -2888083.9
A11: 2023/12
A14: PERIODO | B14: DEBITOS | C14: CRÉDITOS | L14: CRED ANT
B15: 563 | C15: 562 | D15: 520 | E15: 528 | F15: 535 | G15: 544 | H15: 779 | I15: TOTAL | L15: 504
A16: 2023/04 | B16: 0 | C16: 2529312 | D16: 28581391 | E16: 0 | F16: 0 | G16: 0 | H16: 0 | I16: =SUM(D16:H16) -> 28581391 | J16: =+B3-I16 -> 0 | L16: 0
A17: 2023/05 | B17: 0 | C17: 722970 | D17: 371481 | E17: 0 | F17: 0 | G17: 0 | H17: 0 | I17: =SUM(D17:H17) -> 371481 | J17: =+B4-I17 -> 0 | L17: 0
A18: 2023/06 | B18: 0 | C18: 3679423 | D18: 804156 | E18: -15609 | F18: 30671852 | G18: 0 | H18: 0 | I18: =SUM(D18:H18) -> 31460399 | J18: =+B5-I18 -> 0 | L18: 35314377 | M18: =+D3+D4-L18 -> -6361509.2
A19: 2023/07 | I19: =SUM(D19:H19) -> 0 | J19: =+B6-I19 -> 16692628
A20: 2023/08 | I20: =SUM(D20:H20) -> 0 | J20: =+B7-I20 -> 21720855
A21: 2023/09 | I21: =SUM(D21:H21) -> 0 | J21: =+B8-I21 -> 3828075
A22: 2023/10 | I22: =SUM(D22:H22) -> 0 | J22: =+B9-I22 -> 14144169
A23: 2023/11 | I23: =SUM(D23:H23) -> 0 | J23: =+B10-I23 -> 1176728
A24: 2023/12 | I24: =SUM(D24:H24) -> 0 | J24: =+B11-I24 -> 0
A28: 562 - MONTO SIN DERECHO A CRÉDITO FISCAL
A29: 520 - CREDITOS RECIBIDOS Y REINTEGRADOS
A30: 528 - NOTAS DE CRÉDITO
A31: 535 - CREDITOS, RECUPEROS Y REINTEGROS
A32: 544 - RECUPERO IMPUESTO AL DIESEL
A33: 779 - MONTO DE IVA POSTERGADO

Sheet Facturas
A1: FECHA | B1: FACTURA | C1: PROVEEDOR | D1: NETO | E1: EXENTO | F1: IVA | G1: BRUTO | H1: DETALLE GTO | I1: PAGO | J1: MEDIO | L1: COMP
A3: 44994 | B3: 000000041 | C3: RSM CHILE LTDA | D3: 0 | E3: 321152 | F3: =+D3*0.19 -> 0 | G3: =SUM(D3:F3) -> 321152 | H3: ESTUDIO CONTABLE | I3: 45007 | J3: TRANSFERENCIA | L3: 2023/03
A4: 44994 | B4: 000000110 | C4: RSM CHILE LTDA | D4: 0 | E4: 722592 | F4: =+D4*0.19 -> 0 | G4: =SUM(D4:F4) -> 722592 | H4: ESTUDIO CONTABLE | I4: 45007 | J4: TRANSFERENCIA | L4: 2023/03
A5: 44994 | B5: 000000193 | C5: RSM CHILE LTDA | D5: 0 | E5: 722592 | F5: =+D5*0.19 -> 0 | G5: =SUM(D5:F5) -> 722592 | H5: ESTUDIO CONTABLE | I5: 45007 | J5: TRANSFERENCIA | L5: 2023/03
A6: 44999 | B6: 000000234 | C6: RSM CHILE LTDA | D6: 0 | E6: 722826 | F6: =+D6*0.19 -> 0 | G6: =SUM(D6:F6) -> 722826 | H6: ESTUDIO CONTABLE | I6: 45007 | J6: TRANSFERENCIA | L6: 2023/03
A7: 44999 | B7: 000000235 | C7: RSM CHILE LTDA | D7: 0 | E7: 722826 | F7: =+D7*0.19 -> 0 | G7: =SUM(D7:F7) -> 722826 | H7: ESTUDIO CONTABLE | I7: 45007 | J7: TRANSFERENCIA | L7: 2023/03
A8: 44999 | B8: 000000236 | C8: RSM CHILE LTDA | D8: 0 | E8: 963768 | F8: =+D8*0.19 -> 0 | G8: =SUM(D8:F8) -> 963768 | H8: ESTUDIO CONTABLE | I8: 45007 | J8: TRANSFERENCIA | L8: 2023/03
A9: 45006 | B9: 000000269 | C9: RSM CHILE LTDA | D9: 0 | E9: 413175 | F9: =+D9*0.19 -> 0 | G9: =SUM(D9:F9) -> 413175 | H9: ESTUDIO CONTABLE | I9: 45007 | J9: TRANSFERENCIA | L9: 2023/03
D10: =SUM(D3:D9) -> 0 | E10: =SUM(E3:E9) -> 4588931 | F10: =SUM(F3:F9) -> 0 | G10: =SUM(G3:G9) -> 4588931
A12: 45009 | B12: 000085424 | C12: PLAZA EL BOSQUE NUEVA LAS CONDES | D12: 280986 | E12: 0 | F12: =+D12*0.19 -> 53387.34 | G12: =SUM(D12:F12) -> 334373.34 | H12: HOTEL FERNANDO | L12: 2023/04
A13: 45010 | B13: 000036018 | C13: HOTELES DIRECTOR LTDA | D13: 2002000 | E13: 0 | F13: =+D13*0.19 -> 380380 | G13: =SUM(D13:F13) -> 2382380 | H13: HOTEL CURSO BELDEN | I13: 44995 | J13: TRANSFERENCIA | L13: 2023/04
A14: 45019 | B14: 000000350 | C14: RSM CHILE LTDA | D14: 0 | E14: 948492 | F14: =+D14*0.19 -> 0 | G14: =SUM(D14:F14) -> 948492 | H14: ESTUDIO CONTABLE | I14: 45033 | J14: TRANSFERENCIA | L14: 2023/04
A15: 45019 | B15: 000002098 | C15: RSM CHILE LTDA | D15: 0 | E15: 1580820 | F15: =+D15*0.19 -> 0 | G15: =SUM(D15:F15) -> 1580820 | H15: ESTUDIO CONTABLE | I15: 45062 | J15: TRANSFERENCIA | L15: 2023/04
A16: 45020 | B16: 000326069 | C16: SONDA SA | D16: 124665425 | E16: 0 | F16: =+D16*0.19 -> 23686431 | G16: =SUM(D16:F16) -> 1.4835186e+08 | H16: EQUIPOS CISCO | I16: 45028 | J16: TRANSFERENCIA | L16: 2023/04
A17: 45028 | B17: 000126973 | C17: KOLFF SPA | D17: 6244605 | E17: 0 | F17: =+D17*0.19 -> 1186474.9 | G17: =SUM(D17:F17) -> 7431080 | H17: EQUIPOS RITTAL | I17: 45030 | J17: TRANSFERENCIA | L17: 2023/04
A18: 45028 | B18: 000126975 | C18: KOLFF SPA | D18: 16999750 | E18: 0 | F18: =+D18*0.19 -> 3229952.5 | G18: =SUM(D18:F18) -> 20229702 | H18: SERVICIOS | I18: 45030 | J18: TRANSFERENCIA | L18: 2023/04
A19: 45034 | B19: 006055073 | C19: BANCO ITAU CORPBANCA | D19: 88930 | E19: 0 | F19: =+D19*0.19 -> 16896.7 | G19: =SUM(D19:F19) -> 105826.7 | H19: GASTOS BANCARIOS | I19: 45034 | J19: DEBITO BANCO | L19: 2023/04
A20: 45041 | B20: 006063030 | C20: BANCO ITAU CORPBANCA | D20: 146656 | E20: 0 | F20: =+D20*0.19 -> 27864.64 | G20: =SUM(D20:F20) -> 174520.64 | H20: GASTOS BANCARIOS | I20: 45041 | J20: DEBITO BANCO | L20: 2023/04
D21: =SUM(D12:D20) -> 150428352 | E21: =SUM(E12:E20) -> 2529312 | F21: =SUM(F12:F20) -> 28581387 | G21: =SUM(G12:G20) -> 1.8153905e+08
A23: 45048 | B23: 000000468 | C23: RSM CHILE LTDA | D23: 0 | E23: 722970 | F23: =+D23*0.19 -> 0 | G23: =SUM(D23:F23) -> 722970 | H23: ESTUDIO CONTABLE | I23: 45062 | J23: TRANSFERENCIA | L23: 2023/05
A24: 45050 | B24: 000000503 | C24: EASY POINT LOGISTICS SPA | D24: 215345 | E24: 0 | F24: =+D24*0.19 -> 40915.55 | G24: =SUM(D24:F24) -> 256260.55 | H24: SHIP 0004 | I24: 45050 | J24: EASY POINT | L24: 2023/05
A25: 45051 | B25: 000696508 | C25: FEDEX EXPRESS CHILE SPA | D25: 176502 | E25: 0 | F25: =+D25*0.19 -> 33535.38 | G25: =SUM(D25:F25) -> 210037.38 | H25: SHIP 0004 | I25: 45050 | J25: EASY POINT | L25: 2023/05
A26: 45055 | B26: 006085902 | C26: BANCO ITAU CORPBANCA | D26: 1432 | E26: 0 | F26: =+D26*0.19 -> 272.08 | G26: =SUM(D26:F26) -> 1704.08 | H26: GASTOS BANCARIOS | I26: 45055 | J26: DEBITO BANCO | L26: 2023/05
A27: 45055 | B27: 006097076 | C27: BANCO ITAU CORPBANCA | D27: 89662 | E27: 0 | F27: =+D27*0.19 -> 17035.78 | G27: =SUM(D27:F27) -> 106697.78 | H27: GASTOS BANCARIOS | I27: 45055 | J27: DEBITO BANCO | L27: 2023/05
A28: 45063 | B28: 003519638 | C28: DHL EXPRESS (CHILE) LTDA | D28: 263907 | E28: 0 | F28: =+D28*0.19 -> 50142.33 | G28: =SUM(D28:F28) -> 314049.33 | H28: SHIP 0005 | I28: 45062 | J28: EASY POINT | L28: 2023/05
A29: 45064 | B29: 000062043 | C29: ARANEDA MEZA, MARIO | D29: 128425 | E29: 0 | F29: =+D29*0.19 -> 24400.75 | G29: =SUM(D29:F29) -> 152825.75 | H29: SHIP 0004 | I29: 45050 | J29: EASY POINT | L29: 2023/05
A30: 45064 | B30: 000062044 | C30: ARANEDA MEZA, MARIO | D30: 128425 | E30: 0 | F30: =+D30*0.19 -> 24400.75 | G30: =SUM(D30:F30) -> 152825.75 | H30: SHIP 0005 | I30: 45062 | J30: EASY POINT | L30: 2023/05
A31: 45065 | B31: 000957357 | C31: UPS DE CHILE LTDA | D31: 116071 | E31: 0 | F31: =+D31*0.19 -> 22053.49 | G31: =SUM(D31:F31) -> 138124.49 | H31: SHIP 0008 | I31: 45064 | J31: TRANSFERENCIA | L31: 2023/05
A32: 45065 | B32: 000957358 | C32: UPS DE CHILE LTDA | D32: 116071 | E32: 0 | F32: =+D32*0.19 -> 22053.49 | G32: =SUM(D32:F32) -> 138124.49 | H32: SHIP 0009 | I32: 45064 | J32: TRANSFERENCIA | L32: 2023/05
A33: 45062 | B33: 000000533 | C33: EASY POINT LOGISTICS SPA | D33: 215884 | E33: 0 | F33: =+D33*0.19 -> 41017.96 | G33: =SUM(D33:F33) -> 256901.96 | H33: SHIP 0005 | I33: 45062 | J33: EASY POINT | L33: 2023/05
A34: 45071 | B34: 002883004 | C34: SERV AEROPORTUARIOS AEROSAN SA | D34: 100933 | E34: 0 | F34: =+D34*0.19 -> 19177.27 | G34: =SUM(D34:F34) -> 120110.27 | H34: SHIP 0006 | I34: 45069 | J34: EASY POINT | L34: 2023/05
... A39: 45076 | B39: 000062154 | C39: ARANEDA MEZA, MARIO | D39: 83217 | E39: 0 | F39: =+D39*0.19 -> 15811.23 | G39: =SUM(D39:F39) -> 99028.23 | H39: SHIP 0006 | I39: 45069 | J39: EASY POINT | L39: 2023/05
D40: =SUM(D23:D39) -> 1955163 | E40: =SUM(E23:E39) -> 722970 | F40: =SUM(F23:F39) -> 371480.97 | G40: =SUM(G23:G39) -> 3049614
A42: 45050 | B42: 3670087762-5 | C42: TESORERIA GENERAL DE LA REPUBLICA | D42: 0 | E42: =379.94*805.21 -> 305931.49 | F42: =1275.32*805.21 -> 1026900.4 | G42: =SUM(D42:F42) -> 1332831.9 | H42: SHIP 0004 | I42: 45050 | J42: EASY POINT | L42: 2023/06
A43: 45062 | B43: 3670088084-7 | C43: TESORERIA GENERAL DE LA REPUBLICA | D43: 0 | E43: =466.77*805.21 -> 375847.87 | F43: =1566.78*805.21 -> 1261586.9 | G43: =SUM(D43:F43) -> 1637434.8 | H43: SHIP 0005 | I43: 45062 | J43: EASY POINT | L43: 2023/06
A44: 45064 | B44: 401959436-5 | C44: TESORERIA GENERAL DE LA REPUBLICA | D44: 0 | E44: =107.5*805.21 -> 86560.075 | F44: =360.85*805.21 -> 290560.03 | G44: =SUM(D44:F44) -> 377120.1 | H44: SHIP 0009 | I44: 45064 | J44: UPS | L44: 2023/06
A45: 45064 | B45: 401959437-3 | C45: TESORERIA GENERAL DE LA REPUBLICA | D45: 0 | E45: =162.21*805.21 -> 130613.11 | F45: =544.47*805.21 -> 438412.69 | G45: =SUM(D45:F45) -> 569025.8 | H45: SHIP 0008 | I45: 45064 | J45: UPS | L45: 2023/06
A46: 45069 | B46: 000229152 | C46: MSL CHILE SA | D46: 40012 | E46: 0 | F46: =+D46*0.19 -> 7602.28 | G46: =SUM(D46:F46) -> 47614.28 | H46: SHIP 0006 | I46: 45069 | J46: EASY POINT | L46: 2023/06
A47: 45069 | B47: 000052012 | C47: MSL CHILE SA | D47: 0 | E47: 1000956 | F47: =+D47*0.19 -> 0 | G47: =SUM(D47:F47) -> 1000956 | H47: SHIP 0006 | I47: 45069 | J47: EASY POINT | L47: 2023/06
A48: 45069 | B48: 000000551 | C48: EASY POINT LOGISTICS SPA | D48: 216030 | E48: 0 | F48: =+D48*0.19 -> 41045.7 | G48: =SUM(D48:F48) -> 257075.7 | H48: SHIP 0006 | I48: 45069 | J48: EASY POINT | L48: 2023/06
...

Sheet Easy Point
A1: FECHA | B1: NUMERO | C1: TITULAR | D1: MONTO | E1: SHIP
A2: 45050 | B2: 000000503 | C2: EASY POINT LOGISTICS SPA | D2: 256260.55 | E2: SHIP 0004 | G2: PAGOS MULTIPLES
A3: 45051 | B3: 000696508 | C3: FEDEX EXPRESS CHILE SPA | D3: 210037.38 | E3: SHIP 0004
A4: 45051 | B4: 3670087762-5 | C4: TESORERIA GENERAL DE LA REPUBLICA | D4: 1332831.9 | E4: SHIP 0004 | G4: 45069 | H4: SHIP 0004 | I4: 42587 | J4: SALDO
A5: 45064 | B5: 000062043 | C5: ARANEDA MEZA, MARIO | D5: 152825.75 | E5: SHIP 0004 | G5: 45069 | H5: SHIP 0005 | I5: 146606 | J5: SALDO
C6: MENSAJERIA | D6: 17000 | G6: 45069 | H6: SHIP 0006 | I6: 4904470 | J6: IMPO
D7: =SUM(D2:D6) -> 1968955.6 | I7: =SUM(I4:I6) -> 5093663
A8: 45051 | B8: SHIP 0004 | C8: TRANSFERENCIA BANCARIA | D8: -1926369
A9: 45069 | B9: VS SHIPS | C9: TRANSFERENCIA BANCARIA | D9: =-I4 -> -42587 | G9: 45112 | H9: SHIP 0010 | I9: 170853 | J9: SALDO
D10: =SUM(D7:D9) -> -0.4154 | G10: 45112 | H10: SHIP 0013 | I10: 195857 | J10: SALDO
G11: 45112 | H11: SHIP 0007 | I11: -184373 | J11: SALDO
A12: 45062 | B12: 3670088084-7 | C12: TESORERIA GENERAL DE LA REPUBLICA | D12: 1637434.8 | E12: SHIP 0005 | I12: =SUM(I9:I11) -> 182337
A13: 45063 | B13: 003519638 | C13: DHL EXPRESS (CHILE) LTDA | D13: 314049.33 | E13: SHIP 0005
A14: 45064 | B14: 000062044 | C14: ARANEDA MEZA, MARIO | D14: 152825.75 | E14: SHIP 0005 | G14: 45132 | H14: SHIP 0014 | I14: 4923872 | J14: IMPO
A15: 45062 | B15: 000000533 | C15: EASY POINT LOGISTICS SPA | D15: 256901.96 | E15: SHIP 0005 | G15: 45132 | H15: SHIP 0015 | I15: -154547 | J15: SALDO
C16: MENSAJERIA | D16: 17000 | I16: =SUM(I14:I15) -> 4769325
D17: =SUM(D12:D16) -> 2378211.8
A18: 45062 | B18: SHIP 0005 | C18: TRANSFERENCIA BANCARIA | D18: -2231607 | G18: 45156 | H18: SHIP 0021 | I18: 9319428 | J18: =I18-9054180 -> 265248
A19: 45069 | B19: VS SHIPS | C19: TRANSFERENCIA BANCARIA | D19: =-I5 -> -146606 | G19: 45156 | H19: SHIP 0014 | I19: -257891
D20: =SUM(D17:D19) -> -1.1645 | G20: 45156 | H20: SHIP 0016 | I20: -7359
I21: =SUM(I18:I20) -> 9054178
A22: 45065 | B22: 000957357 | C22: UPS DE CHILE LTDA | D22: 138124.49 | E22: SHIP 0008
A23: 45077 | B23: 000000564 | C23: EASY POINT LOGISTICS SPA | D23: 128637.81 | E23: SHIP 0008 | G23: 45182 | H23: SHIP 0021 | I23: 80084 | J23: SALDO
A24: 45079 | B24: 401959437-3 | C24: TESORERIA GENERAL DE LA REPUBLICA | D24: 569025.8 | E24: SHIP 0008 | G24: 45182 | H24: SHIP 0019 | I24: 135521 | J24: SALDO
D25: =SUM(D22:D24) -> 835788.1 | I25: =SUM(I23:I24) -> 215605
A26: 45064 | B26: SHIP 0008 | C26: TRANSFERENCIA BANCARIA | D26: -707150.49
A27: 45092 | B27: EASY POINT | C27: TRANSFERENCIA BANCARIA | D27: =-D23 -> -128637.81 | G27: 45191 | H27: SHIP 0023 | I27: 4102854
D28: =SUM(D25:D27) -> -0.1972 | G28: 45191 | H28: SHIP 0014 | I28: -257891 | J28: descontado doble
G29: 45191 | H29: SHIP 0016 | I29: -7359 | J29: descontado doble
A30: 45065 | B30: 000957358 | C30: UPS DE CHILE LTDA | D30: 138124.49 | E30: SHIP 0009 | G30: 45191 | H30: SHIP 0022 | I30: -94678 | J30: saldo mail 15/09
A31: 45077 | B31: 000000565 | C31: EASY POINT LOGISTICS SPA | D31: 128637.81 | E31: SHIP 0009 | I31: 3742926
A32: 45079 | B32: 401959436-5 | C32: TESORERIA GENERAL DE LA REPUBLICA | D32: 377120.1 | E32: SHIP 0009
D33: =SUM(D30:D32) -> 643882.4 | G33: 45191 | H33: SHIP 0014 | I33: =-I28 -> 257891 | J33: descontado doble
A34: 45064 | B34: SHIP 0009 | C34: TRANSFERENCIA BANCARIA | D34: -515244.49 | G34: 45191 | H34: SHIP 0016 | I34: =-I29 -> 7359 | J34: descontado doble
A35: 45092 | B35: EASY POINT | C35: TRANSFERENCIA BANCARIA | D35: =-D31 -> -128637.81 | G35: 45194 | H35: SHIP 0022 | I35: =-D223 -> -214199.52 | J35: saldo revisado c/ Caro 25/09
D36: =SUM(D33:D35) -> 0.1035 | G36: 45194 | H36: SHIP 0023 | I36: =-D236 -> -30501 | J36: ok mail 06/10
I37: =SUM(I33:I36) -> 20549.479
A38: 45071 | B38: 002883004 | C38: SERV AEROPORTUARIOS AEROSAN SA | D38: 120110.27 | E38: SHIP 0006 | G38: 45210 | H38: TRANSFERENCIA | I38: -20549.479
A39: 45071 | B39: 000005579 | C39: MOYA VARAS, MARINA | D39: 53550 | E39: SHIP 0006 | I39: =SUM(I37:I38) -> 0
A40: 45076 | B40: 000062153 | C40: ARANEDA MEZA, MARIO | D40: 152825.75 | E40: SHIP 0006
...
