Workbook

Sheet Divisas
A2: FECHA | B2: DETALLE | C2: CLP | D2: TC | E2: USD | F2: SALDO | H2: FECHA | I2: DETALLE | J2: UYU | K2: TC | L2: USD | M2: SALDO
A3: 44966 | B3: COMISION | C3: -35318 | D3: =+D6 -> 825.6 | E3: =+C3/D3 -> -42.778585 | H3: 45134 | I3: INCIAL | J3: 833.38 | K3: 38 | L3: =+J3/K3 -> 21.931053 | M3: =+L3 -> 21.931053
A4: 44966 | B4: IVA | C4: -6710 | D4: =+D6 -> 825.6 | E4: =+C4/D4 -> -8.1274225 | H4: 45139 | I4: GTOS BCO | J4: -115 | K4: =+$K$3 -> 38 | L4: =+J4/K4 -> -3.0263158
A5: 44967 | B5: TRANSFERENCIA | C5: 43000 | D5: =+D6 -> 825.6 | E5: =+C5/D5 -> 52.083333 | H5: 45140 | I5: CO-1000 CAV | J5: -535.53 | K5: =+$K$3 -> 38 | L5: =+J5/K5 -> -14.092895
A6: 44984 | B6: COMPRA MC | C6: 82560 | D6: =+C6/E6 -> 825.6 | E6: 100 | H6: 45140 | I6: GTOS BCO | J6: -71.24 | K6: =+$K$3 -> 38 | L6: =+J6/K6 -> -1.8747368
A7: 44984 | B7: COMISION | C7: -35500 | D7: =+D6 -> 825.6 | E7: =+C7/D7 -> -42.999031 | H7: 45140 | I7: COMPRA MC | J7: 540000 | K7: =+J7/L7 -> 36.950009 | L7: 14614.34
A8: 44984 | B8: IVA | C8: -6745 | D8: =+D6 -> 825.6 | E8: =+C8/D8 -> -8.1698159 | F8: =SUM(E3:E8) -> 50.008479 | H8: 45141 | I8: CO-1000 CAV | J8: -111.61 | K8: =+$K$3 -> 38 | L8: =+J8/K8 -> -2.9371053
A9: 44994 | B9: COMPRA MC | C9: 2389500 | D9: =+C9/E9 -> 796.5 | E9: 3000 | H9: 45141 | I9: CO-1000 CAV | J9: =-284993.47-J8 -> -284881.86 | K9: =+$K$7 -> 36.950009 | L9: =+J9/K9 -> -7709.9266
A10: 44995 | B10: HOTEL DIRECTOR | C10: -41287 | D10: =+D6 -> 825.6 | E10: =+C10/D10 -> -50.008479 | H10: 45141 | I10: GTOS BCO | J10: -71.93 | K10: =+$K$7 -> 36.950009 | L10: =+J10/K10 -> -1.9466842
A11: 44995 | B11: HOTEL DIRECTOR | C11: =-2382380-C10 -> -2341093 | D11: =+D9 -> 796.5 | E11: =+C11/D11 -> -2939.2254 | H11: 45141 | I11: CO-1000 CAV | J11: -250000 | K11: =+$K$7 -> 36.950009 | L11: =+J11/K11 -> -6765.8981
A12: 45007 | B12: COMPRA MC | C12: 4903002 | D12: =+C12/E12 -> 819.9 | E12: 5980 | H12: 45141 | I12: GTOS BCO | J12: -71.93 | K12: =+$K$7 -> 36.950009 | L12: =+J12/K12 -> -1.9466842
A13: 45008 | B13: RSM | C13: -48407 | D13: =+D9 -> 796.5 | E13: =+C13/D13 -> -60.774639 | H13: 45149 | I13: RSM | J13: -1600 | K13: =+$K$7 -> 36.950009 | L13: =+J13/K13 -> -43.301748 | M13: =+M3+SUM(L4:L13) -> 91.320139
A14: 45008 | B14: RSM | C14: =-4588931-C13 -> -4540524 | D14: =+D12 -> 819.9 | E14: =+C14/D14 -> -5537.8997 | F14: =+F8+SUM(E9:E14) -> 442.10026 | H14: 45170 | I14: COMPRA MC | J14: 7370 | K14: =+J14/L14 -> 36.85 | L14: 200
A15: 45027 | B15: COMPRA MC | C15: 150000000 | D15: =+C15/E15 -> 809.49999 | E15: 185299.57 | H15: 45170 | I15: GTOS BCO | J15: -115 | K15: =+$K$7 -> 36.950009 | L15: =+J15/K15 -> -3.1123131
A16: 45028 | B16: SONDA | C16: -362478 | D16: =+D12 -> 819.9 | E16: =+C16/D16 -> -442.10026 | H16: 45173 | I16: CO-1000 CAV | J16: -3259.28 | K16: =+$K$7 -> 36.950009 | L16: =+J16/K16 -> -88.207826
A17: 45028 | B17: SONDA | C17: =-148351856-C16 -> -147989378 | D17: =+D15 -> 809.49999 | E17: =+C17/D17 -> -182815.79 | H17: 45173 | I17: CO-1000 CAV | J17: =-7022.06-J16 -> -3762.78 | K17: =+$K$14 -> 36.85 | L17: =+J17/K17 -> -102.11072
A18: 45028 | B18: COMPRA MC | C18: 149145000 | D18: =+C18/E18 -> 815 | E18: 183000 | H18: 45173 | I18: GTOS BCO | J18: -71.08 | K18: =+$K$14 -> 36.85 | L18: =+J18/K18 -> -1.9289009
A19: 45029 | B19: KOLFF | C19: -2010622 | D19: =+D15 -> 809.49999 | E19: =+C19/D19 -> -2483.7826 | H19: 45180 | I19: VISA DEBITO | J19: -1334.1 | K19: =+$K$14 -> 36.85 | L19: =+J19/K19 -> -36.203528 | M19: =+M13+SUM(L14:L19) -> 59.756852
A20: 45029 | B20: KOLFF | C20: =-27660783-C19 -> -25650161 | D20: =+$D$18 -> 815 | E20: =+C20/D20 -> -31472.59 | H20: 45200 | I20: GTOS BCO | J20: -115 | K20: =+$K$14 -> 36.85 | L20: =+J20/K20 -> -3.1207598 | M20: =+M19+L20 -> 56.636092
A21: 45033 | B21: RSM | C21: -948492 | D21: =+$D$18 -> 815 | E21: =+C21/D21 -> -1163.7939 | H21: 45231 | I21: GTOS BCO | J21: -115 | K21: =+$K$14 -> 36.85 | L21: =+J21/K21 -> -3.1207598
A22: 45033 | B22: FEDEX | C22: -522269 | D22: =+$D$18 -> 815 | E22: =+C22/D22 -> -640.82086 | H22: 45257 | I22: GTOS BCO | J22: -1613.55 | K22: =+$K$14 -> 36.85 | L22: =+J22/K22 -> -43.786974 | M22: =+M20+SUM(L21:L22) -> 9.7283582
A23: 45033 | B23: SII - IVA | C23: -66627802 | D23: =+$D$18 -> 815 | E23: =+C23/D23 -> -81751.904 | H23: 45261 | I23: GTOS BCO | J23: -115 | K23: =+$K$14 -> 36.85 | L23: =+J23/K23 -> -3.1207598 | M23: =+M22+L23 -> 6.6075984
A24: 45034 | B24: COMISION | C24: -88930 | D24: =+$D$18 -> 815 | E24: =+C24/D24 -> -109.11656 | H24: 45292 | I24: GTOS BCO | J24: -115 | K24: =+$K$14 -> 36.85 | L24: =+J24/K24 -> -3.1207598 | M24: =+M23+L24 -> 3.4868385
A25: 45034 | B25: IVA | C25: -16897 | D25: =+$D$18 -> 815 | E25: =+C25/D25 -> -20.732515 | K25: =+$K$14 -> 36.85 | L25: =+J25/K25 -> 0
A26: 45035 | B26: UPS | C26: -406965 | D26: =+$D$18 -> 815 | E26: =+C26/D26 -> -499.34356 | K26: =+$K$14 -> 36.85 | L26: =+J26/K26 -> 0
A27: 45041 | B27: COMISION | C27: -107629 | D27: =+D18 -> 815 | E27: =+C27/D27 -> -132.06012 | K27: =+$K$14 -> 36.85 | L27: =+J27/K27 -> 0
A28: 45041 | B28: COMISION | C28: -107629 | D28: =+D18 -> 815 | E28: =+C28/D28 -> -132.06012 | F28: =+F14+SUM(E15:E28) -> 67077.578 | K28: =+$K$14 -> 36.85 | L28: =+J28/K28 -> 0
A29: 45051 | B29: C-01523 ADUANA | C29: -1926369 | D29: =+D18 -> 815 | E29: =+C29/D29 -> -2363.6429 | K29: =+$K$14 -> 36.85 | L29: =+J29/K29 -> 0
A30: 45055 | B30: COMISION | C30: =-1432-89662 -> -91094 | D30: =+$D$18 -> 815 | E30: =+C30/D30 -> -111.77178 | K30: =+$K$14 -> 36.85 | L30: =+J30/K30 -> 0
A31: 45055 | B31: IVA | C31: =-272-17036 -> -17308 | D31: =+$D$18 -> 815 | E31: =+C31/D31 -> -21.23681 | K31: =+$K$14 -> 36.85 | L31: =+J31/K31 -> 0
A32: 45062 | B32: RSM | C32: -2303790 | D32: =+D23 -> 815 | E32: =+C32/D32 -> -2826.7362
A33: 45062 | B33: SHIP 0005 | C33: -2231607 | D33: =+D23 -> 815 | E33: =+C33/D33 -> -2738.1681
A34: 45064 | B34: UPS | C34: -707150 | D34: =+D23 -> 815 | E34: =+C34/D34 -> -867.66871 | J34: =SUM(J3:J33) -> 128.49 | L34: =SUM(L3:L33) -> 3.4868385
A35: 45064 | B35: UPS | C35: -515245 | D35: =+$D$18 -> 815 | E35: =+C35/D35 -> -632.20245
A36: 45069 | B36: SHIP 0006 | C36: -5093663 | D36: =+$D$18 -> 815 | E36: =+C36/D36 -> -6249.8933 | L36: 4813.69 | M36: TOTAL USD
A37: 45075 | B37: DHL | C37: -210088 | D37: =+$D$18 -> 815 | E37: =+C37/D37 -> -257.77669
A38: 45075 | B38: UPS | C38: -684959 | D38: =+$D$18 -> 815 | E38: =+C38/D38 -> -840.44049 | F38: =+F28+SUM(E29:E38) -> 50168.04 | L38: =SUM(L34:L36) -> 4817.1768
A39: 45084 | B39: SHIP 010 | C39: -1097271 | D39: =+$D$18 -> 815 | E39: =+C39/D39 -> -1346.3448
A40: 45086 | B40: SHIP 010 | C40: =-(7000000*2+416063) -> -14416063 | D40: =+$D$18 -> 815 | E40: =+C40/D40 -> -17688.421
A41: 45092 | B41: SHIP 013 | C41: -1159608 | D41: =+$D$18 -> 815 | E41: =+C41/D41 -> -1422.8319
...

Sheet Mensuales
B2: CHILE | E2: URUGUAY
B3: USD | C3: CLP | D3: TOTAL | E3: USD | F3: UYU | G3: TOTAL
A4: *FEBRERO 23 | B4: 50099.5 | C4: =+Divisas!F8 -> 50.008479 | D4: =SUM(B4:C4) -> 50149.508 | E4: 47948.64 | F4: =+Divisas!M3 -> 21.931053 | G4: =SUM(E4:F4) -> 47970.571
A5: *MARZO 23 | B5: 83412.26 | C5: =+Divisas!F14 -> 442.10026 | D5: =SUM(B5:C5) -> 83854.36 | E5: 14178.96 | F5: =+Divisas!M3 -> 21.931053 | G5: =SUM(E5:F5) -> 14200.891
A6: *ABRIL 23 | B6: 177276 | C6: =+Divisas!F28 -> 67077.578 | D6: =SUM(B6:C6) -> 244353.58 | E6: 65430.66 | F6: =+Divisas!M3 -> 21.931053 | G6: =SUM(E6:F6) -> 65452.591
A7: *MAYO 23 | B7: 177276 | C7: =+Divisas!F38 -> 50168.04 | D7: =SUM(B7:C7) -> 227444.04 | E7: 35722.54 | F7: =+Divisas!M3 -> 21.931053 | G7: =SUM(E7:F7) -> 35744.471
A8: *JUNIO 23 | B8: 156081 | C8: =+Divisas!F52 -> 13075.619 | D8: =SUM(B8:C8) -> 169156.62 | E8: 30885.39 | F8: =+Divisas!M3 -> 21.931053 | G8: =SUM(E8:F8) -> 30907.321
A9: *JULIO 23 | B9: 137697 | C9: =+Divisas!F70 -> 2032.5287 | D9: =SUM(B9:C9) -> 139729.53 | E9: 11033.86 | F9: =+Divisas!M3 -> 21.931053 | G9: =SUM(E9:F9) -> 11055.791
A10: *AGOSTO 23 | B10: 53797 | C10: =+Divisas!F89 -> 3429.5823 | D10: =SUM(B10:C10) -> 57226.582 | E10: 9097.25 | F10: =+Divisas!M13 -> 91.320139 | G10: =SUM(E10:F10) -> 9188.5701
A11: *SEPTIEMBRE 23 | B11: 38897.15 | C11: =+Divisas!F108 -> 621.37102 | D11: =SUM(B11:C11) -> 39518.521 | E11: 23059.25 | F11: =+Divisas!M19 -> 59.756852 | G11: =SUM(E11:F11) -> 23119.007
A12: *OCTUBRE 23 | B12: 610701.1 | C12: =+Divisas!F140 -> 176.82873 | D12: =SUM(B12:C12) -> 610877.93 | E12: 34914.92 | F12: =+Divisas!M20 -> 56.636092 | G12: =SUM(E12:F12) -> 34971.556
A13: *NOVIEMBRE 23 | B13: 488531.3 | C13: =+Divisas!F177 -> 1097.504 | D13: =SUM(B13:C13) -> 489628.8 | E13: 14232.28 | F13: =+Divisas!M22 -> 9.7283582 | G13: =SUM(E13:F13) -> 14242.008
A14: *DICIEMBRE 23 | B14: 189563.43 | C14: =+Divisas!F199 -> 641.85083 | D14: =SUM(B14:C14) -> 190205.28 | E14: 8729.42 | F14: =+Divisas!M23 -> 6.6075984 | G14: =SUM(E14:F14) -> 8736.0276
A15: *ENERO 24 | B15: 78397.63 | C15: =+Divisas!F220 -> 229.98708 | D15: =SUM(B15:C15) -> 78627.617 | E15: 2862.98 | F15: =+Divisas!M24 -> 3.4868385 | G15: =SUM(E15:F15) -> 2866.4668
A16: *FEBRERO 24 | B16: 78397.63 | C16: =+Divisas!F221 -> 137.26529 | D16: =SUM(B16:C16) -> 78534.895 | E16: 2601.8 | F16: =+Divisas!M24 -> 3.4868385 | G16: =SUM(E16:F16) -> 2605.2868
