Workbook
Name MGDATOS: #REF!

Sheet Cuadratura 31.12.2023
A1: Planilla Unificada
A2: Tipo Factura Recibida | E2: Cant.Reg | F2: Exento | G2: Neto | H2: I.V.A. | I2: Otros Imp. | J2: I.V.A. No Rec | K2: Total | L2: Total Ventas
A3: 34 | B3: Factura de Compra Electronica Exenta | E3: =COUNTIF('Planilla Compras unificada'!$B:$B,'Cuadratura 31.12.2023'!A3) -> 5 | F3: =SUMIFS('Planilla Compras unificada'!$H:$H,'Planilla Compras unificada'!$B:$B,'Cuadratura 31.12.2023'!A3) -> 1747472 | G3: =SUMIFS('Planilla Compras unificada'!$I:$I,'Planilla Compras unificada'!$B:$B,'Cuadratura 31.12.2023'!A3) -> 0 | H3: =SUMIFS('Planilla Compras unificada'!$J:$J,'Planilla Compras unificada'!$B:$B,'Cuadratura 31.12.2023'!A3) -> 0 | K3: =SUM(F3:J3) -> 1747472
A4: 33 | B4: Factura de compras Electrónica afectas | E4: =COUNTIF('Planilla Compras unificada'!$B:$B,'Cuadratura 31.12.2023'!A4) -> 20 | F4: =SUMIFS('Planilla Compras unificada'!$H:$H,'Planilla Compras unificada'!$B:$B,'Cuadratura 31.12.2023'!A4) -> 833245 | G4: =SUMIFS('Planilla Compras unificada'!$I:$I,'Planilla Compras unificada'!$B:$B,'Cuadratura 31.12.2023'!A4) -> 222268066 | H4: =SUMIFS('Planilla Compras unificada'!$J:$J,'Planilla Compras unificada'!$B:$B,'Cuadratura 31.12.2023'!A4) -> 42230931 | K4: =SUM(F4:J4) -> 265332242
A5: 61 | B5: Nota Credito Compra Electronica Afecta | E5: =COUNTIF('Planilla Compras unificada'!$B:$B,'Cuadratura 31.12.2023'!A5) -> 0 | F5: =SUMIFS('Planilla Compras unificada'!$H:$H,'Planilla Compras unificada'!$B:$B,'Cuadratura 31.12.2023'!A5) -> 0 | G5: =SUMIFS('Planilla Compras unificada'!$I:$I,'Planilla Compras unificada'!$B:$B,'Cuadratura 31.12.2023'!A5) -> 0 | H5: =SUMIFS('Planilla Compras unificada'!$J:$J,'Planilla Compras unificada'!$B:$B,'Cuadratura 31.12.2023'!A5) -> 0 | K5: =SUM(F5:J5) -> 0
A6: 56 | B6: Nota de Debito de Compra ELECTRONICA | E6: =COUNTIF('Planilla Compras unificada'!$B:$B,'Cuadratura 31.12.2023'!A6) -> 0 | F6: =SUMIFS('Planilla Compras unificada'!$H:$H,'Planilla Compras unificada'!$B:$B,'Cuadratura 31.12.2023'!A6) -> 0 | G6: =SUMIFS('Planilla Compras unificada'!$I:$I,'Planilla Compras unificada'!$B:$B,'Cuadratura 31.12.2023'!A6) -> 0 | H6: =SUMIFS('Planilla Compras unificada'!$J:$J,'Planilla Compras unificada'!$B:$B,'Cuadratura 31.12.2023'!A6) -> 0 | K6: =SUM(F6:J6) -> 0
L7: =+K3+K4-K5+K6 -> 267079714
A8: Total Resumen : | E8: =SUM(E3:E7) -> 25 | F8: =+F3+F4-F5+F6 -> 2580717 | G8: =+G3+G4-G5+G6 -> 222268066 | H8: =+H3+H4-H5+H6 -> 42230931
J9: =SUM(F8:I8) -> 267079714 | L9: =J9-L7 -> 0
A11: MAGNUS
A12: Tipo Factura Recibida | E12: Cant.Reg | F12: Exento | G12: Neto | H12: I.V.A. | I12: Otros Imp. | J12: I.V.A. No Rec | K12: Total | L12: Total Ventas
A13: 34 | B13: Factura de Compra Electronica Exenta | E13: =COUNTIF('MAGNUS LC'!$D:$D,'Cuadratura 31.12.2023'!B13) -> 5 | F13: =SUMIFS('MAGNUS LC'!$K:$K,'MAGNUS LC'!$D:$D,'Cuadratura 31.12.2023'!B13) -> 1747472 | G13: =SUMIFS('MAGNUS LC'!$I:$I,'MAGNUS LC'!$D:$D,'Cuadratura 31.12.2023'!B13) -> 0 | H13: =SUMIFS('MAGNUS LC'!$J:$J,'MAGNUS LC'!$D:$D,'Cuadratura 31.12.2023'!B13) -> 0 | K13: =SUM(F13:J13) -> 1747472
A14: 33 | B14: Factura de compras Electrónica afectas | E14: =COUNTIF('MAGNUS LC'!$D:$D,'Cuadratura 31.12.2023'!B14) -> 20 | F14: =SUMIFS('MAGNUS LC'!$K:$K,'MAGNUS LC'!$D:$D,'Cuadratura 31.12.2023'!B14) -> 833245 | G14: =SUMIFS('MAGNUS LC'!$I:$I,'MAGNUS LC'!$D:$D,'Cuadratura 31.12.2023'!B14) -> 222268066 | H14: =SUMIFS('MAGNUS LC'!$J:$J,'MAGNUS LC'!$D:$D,'Cuadratura 31.12.2023'!B14) -> 42230931 | K14: =SUM(F14:J14) -> 265332242
A15: 61 | B15: Nota Credito Compra Electronica Afecta | E15: =COUNTIF('MAGNUS LC'!$D:$D,'Cuadratura 31.12.2023'!B15) -> 0 | F15: =SUMIFS('MAGNUS LC'!$K:$K,'MAGNUS LC'!$D:$D,'Cuadratura 31.12.2023'!B15) -> 0 | G15: =SUMIFS('MAGNUS LC'!$I:$I,'MAGNUS LC'!$D:$D,'Cuadratura 31.12.2023'!B15)*-1 -> 0 | H15: =SUMIFS('MAGNUS LC'!$J:$J,'MAGNUS LC'!$D:$D,'Cuadratura 31.12.2023'!B15)*-1 -> 0 | K15: =SUM(F15:J15) -> 0
A16: 56 | B16: Nota de Debito de Compra ELECTRONICA | E16: =COUNTIF('MAGNUS LC'!$D:$D,'Cuadratura 31.12.2023'!B16) -> 0 | F16: =SUMIFS('MAGNUS LC'!$K:$K,'MAGNUS LC'!$D:$D,'Cuadratura 31.12.2023'!B16) -> 0 | G16: =SUMIFS('MAGNUS LC'!$I:$I,'MAGNUS LC'!$D:$D,'Cuadratura 31.12.2023'!B16) -> 0 | H16: =SUMIFS('MAGNUS LC'!$J:$J,'MAGNUS LC'!$D:$D,'Cuadratura 31.12.2023'!B16) -> 0 | K16: =SUM(F16:J16) -> 0
L17: =+K13+K14-K15+K16 -> 267079714
A18: Total Resumen : | E18: =SUM(E13:E17) -> 25 | F18: =+F13+F14-F15+F16 -> 2580717 | G18: =+G13+G14-G15+G16 -> 222268066 | H18: =+H13+H14-H15+H16 -> 42230931
J19: =SUM(F18:I18) -> 267079714 | L19: =J19-L17 -> 0
A21: DIFERENCIA
E22: Cant.Reg | F22: Exento | G22: Neto | H22: I.V.A. | I22: Otros Imp. | J22: I.V.A. No Rec | K22: Total | L22: Total Ventas
A23: FACTURA DE GASTOS | E23: =E3-E13 -> 0 | F23: =F3-F13 -> 0 | G23: =G3-G13 -> 0 | H23: =H3-H13 -> 0 | K23: =K3-K13 -> 0
A24: FACTURA ELECTRONICA EXENTA | E24: =+E14-E4 -> 0 | F24: =+F14-F4 -> 0 | G24: =+G14-G4 -> 0 | H24: =+H14-H4 -> 0 | K24: =+K4-K14 -> 0
A25: NOTA DE CREDITO | E25: =+E5-E15 -> 0 | F25: =+F5-F15 -> 0 | G25: =+G5-G15 -> 0 | H25: =+H5-H15 -> 0 | K25: =+K5-K15 -> 0
A26: NOTA DE DEBITO | E26: =E6-E16 -> 0 | F26: =F6-F16 -> 0 | G26: =G6-G16 -> 0 | H26: =H6-H16 -> 0 | K26: =+K6-K16 -> 0

Sheet MAGNUS LC
A1: Libro de Compras
A2: Empresa :PROYESCO CHILE SPA / Periodo : 01/12/23 al 31/12/23
A3: Fecha _x000D_ Documento | B3: Fecha_x000D_ Contab | C3: Correlativo_x000D_ Interno | D3: Tipo Factura_x000D_ Recibida | E3: Nro_x000D_ Factura | F3: R.U.T. | G3: Razon Social | I3: Neto | J3: I.V.A. | K3: Exento | L3: I.V.A Adicional | M3: I.V.A No Rec | N3: Total
A4: 45278 | B4: 45278 | C4: 20231200011 | D4: Declaracion de Ingreso (Importacion) | E4: 402029597 | F4: 608050000 | G4: TGR TESORERIA GENERAL DE LA REPUBLICA | J4: 52333 | N4: 52333
A5: 45261 | B5: 45261 | C5: 20231200001 | D5: Factura de Compra Electronica Exenta | E5: 1331 | F5: 777163124 | G5: RSM CHILE CONTABILIDAD Y PROCESOS LIMITADA | K5: 1043472 | N5: 1043472
A6: 45271 | B6: 45271 | C6: 20231200020 | D6: Factura de Compra Electronica Exenta | E6: 3442 | F6: 760794058 | G6: PESCO CAPACITACIONES LIMITADA | K6: 704000 | N6: 704000
A7: 45267 | B7: 45267 | C7: 20231200024 | D7: Factura de Compra Electronica Exenta | E7: 1805946 | F7: 970230009 | G7: BANCO ITAÚ CHILE
A8: 45288 | B8: 45288 | C8: 20231200025 | D8: Factura de Compra Electronica Exenta | E8: 2026362 | F8: 970230009 | G8: BANCO ITAÚ CHILE
A9: 45289 | B9: 45289 | C9: 20231200026 | D9: Factura de Compra Electronica Exenta | E9: 2028745 | F9: 970230009 | G9: BANCO ITAÚ CHILE
A10: 45267 | B10: 45267 | C10: 20231200002 | D10: Factura de compras Electrónica afectas | E10: 6413164 | F10: 970230009 | G10: BANCO ITAÚ CHILE | I10: 731 | J10: 139 | N10: 870
A11: 45271 | B11: 45271 | C11: 20231200003 | D11: Factura de compras Electrónica afectas | E11: 6426323 | F11: 970230009 | G11: BANCO ITAÚ CHILE | I11: 91422 | J11: 17370 | N11: 108792
A12: 45273 | B12: 45273 | C12: 20231200004 | D12: Factura de compras Electrónica afectas | E12: 6432905 | F12: 970230009 | G12: BANCO ITAÚ CHILE | I12: 96868 | J12: 18405 | N12: 115273
A13: 45279 | B13: 45279 | C13: 20231200005 | D13: Factura de compras Electrónica afectas | E13: 128038 | F13: 968416308 | G13: KOLFF SPA | I13: 6981311 | J13: 1326449 | N13: 8307760
A14: 45279 | B14: 45279 | C14: 20231200006 | D14: Factura de compras Electrónica afectas | E14: 128039 | F14: 968416308 | G14: KOLFF SPA | I14: 6512813 | J14: 1237434 | N14: 7750247
A15: 45279 | B15: 45279 | C15: 20231200007 | D15: Factura de compras Electrónica afectas | E15: 128040 | F15: 968416308 | G15: KOLFF SPA | I15: 3281032 | J15: 623396 | N15: 3904428
A16: 45279 | B16: 45279 | C16: 20231200008 | D16: Factura de compras Electrónica afectas | E16: 128043 | F16: 968416308 | G16: KOLFF SPA | I16: 1540927 | J16: 292776 | N16: 1833703
A17: 45281 | B17: 45281 | C17: 20231200009 | D17: Factura de compras Electrónica afectas | E17: 6441008 | F17: 970230009 | G17: BANCO ITAÚ CHILE | I17: 95565 | J17: 18157 | N17: 113722
A18: 45288 | B18: 45288 | C18: 20231200010 | D18: Factura de compras Electrónica afectas | E18: 6447975 | F18: 970230009 | G18: BANCO ITAÚ CHILE | I18: 97497 | J18: 18524 | N18: 116021
A19: 45261 | B19: 45261 | C19: 20231200012 | D19: Factura de compras Electrónica afectas | E19: 952 | F19: 771903932 | G19: EASY POINT LOGISTICS SPA | I19: 219179 | J19: 41644 | N19: 260823
A20: 45261 | B20: 45261 | C20: 20231200013 | D20: Factura de compras Electrónica afectas | E20: 230611 | F20: 968518003 | G20: Asesores en Viaje S.A. | I20: 17900 | J20: 3401 | K20: 615760 | N20: 637061
A21: 45261 | B21: 45261 | C21: 20231200014 | D21: Factura de compras Electrónica afectas | E21: 230612 | F21: 968518003 | G21: Asesores en Viaje S.A. | I21: 17900 | J21: 3401 | K21: 217485 | N21: 238786
A22: 45261 | B22: 45261 | C22: 20231200015 | D22: Factura de compras Electrónica afectas | E22: 96 | F22: 774500820 | G22: GRUPO MONTECARLO SPA | I22: 67227 | J22: 12773 | N22: 80000
A23: 45261 | B23: 45261 | C23: 20231200016 | D23: Factura de compras Electrónica afectas | E23: 343259 | F23: 836281004 | G23: SONDA S.A | I23: 202813239 | J23: 38534515 | N23: 241347754
A24: 45261 | B24: 45261 | C24: 20231200017 | D24: Factura de compras Electrónica afectas | E24: 19897331 | F24: 81201000K | G24: CENCOSUD RETAIL S.A. | I24: 19080 | J24: 3626 | N24: 22706
A25: 45263 | B25: 45263 | C25: 20231200018 | D25: Factura de compras Electrónica afectas | E25: 19897339 | F25: 81201000K | G25: CENCOSUD RETAIL S.A. | I25: 79934 | J25: 15188 | N25: 95122
A26: 45268 | B26: 45268 | C26: 20231200019 | D26: Factura de compras Electrónica afectas | E26: 19897358 | F26: 81201000K | G26: CENCOSUD RETAIL S.A. | I26: 17634 | J26: 3350 | N26: 20984
A27: 45274 | B27: 45274 | C27: 20231200021 | D27: Factura de compras Electrónica afectas | E27: 99 | F27: 774500820 | G27: GRUPO MONTECARLO SPA | I27: 57000 | J27: 10830 | N27: 67830
A28: 45279 | B28: 45279 | C28: 20231200022 | D28: Factura de compras Electrónica afectas | E28: 991115 | F28: 789534705 | G28: UNITED PARCEL SERVICE DE CHILE LIMITADA | I28: 40517 | J28: 7698 | N28: 48215
A29: 45282 | B29: 45282 | C29: 20231200023 | D29: Factura de compras Electrónica afectas | E29: 1031 | F29: 771903932 | G29: EASY POINT LOGISTICS SPA | I29: 220290 | J29: 41855 | N29: 262145

Sheet balance
A3: Balance General IFRS
A7: Numero Cuenta | B7: Nombre Cuenta | C7: Valores Acumulados | E7: Saldos | G7: Inventario | I7: Resultados
C8: Debitos | D8: Creditos | E8: Deudor | F8: Acreedor | G8: Activo | H8: Pasivo | I8: Perdidas | J8: Ganancias
A9: 1101201 | B9: FONDO FIJO LOS DOMINICOS | C9: 290796 | D9: 322396 | F9: 31600 | H9: 31600
A10: 1101202 | B10: FONDO FIJO MAIPU | C10: 442010 | D10: 367410 | E10: 74600 | G10: 74600
A11: 1101203 | B11: FONDO FIJO PLAZA EGAÑA | C11: 405688 | D11: 530118 | F11: 124430 | H11: 124430
A12: 1101204 | B12: FONDO FIJO VESPUCIO | C12: 880930 | D12: 780930 | E12: 100000 | G12: 100000
A13: 1101205 | B13: FONDO FIJO TREBOL | C13: 397062 | D13: 461277 | F13: 64215 | H13: 64215
A14: 1101206 | B14: FONDO FIJO COSTANERA CENTER | C14: 574650 | D14: 758950 | F14: 184300 | H14: 184300
A15: 1101207 | B15: FONDO FIJO FLORIDA CENTER | C15: 519635 | D15: 492495 | E15: 27140 | G15: 27140
A16: 1101208 | B16: FONDO FIJO SANTIAGO CENTRO | C16: 1749411 | D16: 1105307 | E16: 644104 | G16: 644104
A17: 1101209 | B17: FONDO FIJO CONCEPCION CENTRO | C17: 0 | D17: 4899 | F17: 4899 | H17: 4899
A18: 1101301 | B18: BANCOS CTA CTE $ | C18: 1801915739 | D18: 1314115527 | E18: 487800212 | G18: 487800212
A19: 1101302 | B19: BANCOS CTA CTE US$ | C19: 86763389 | D19: 28552926 | E19: 58210463 | G19: 58210463
A20: 1102106 | B20: DEPOSITO A PLAZO CORREDORA | C20: 4476544 | D20: 0 | E20: 4476544 | G20: 4476544
A21: 1103201 | B21: GASTOS PAGADOS POR ANTICIPADO | C21: 78226426 | D21: 7056642 | E21: 71169784 | G21: 71169784
A22: 1104101 | B22: CLIENTES NACIONALES | C22: 10563630 | D22: 10563630
A23: 1104102 | B23: CLIENTES BOLETAS | C23: 7537524540 | D23: 7317357217 | E23: 220167323 | G23: 220167323
A24: 1104104 | B24: FONDOS POR RENDIR | C24: 16097453 | D24: 13351442 | E24: 2746011 | G24: 2746011
A25: 1104105 | B25: TRANSBANK POR COBRAR TC | C25: 1282967537 | D25: 1179206870 | E25: 103760667 | G25: 103760667
A26: 1104106 | B26: TRANSBANK POR COBRAR TD | C26: 753444795 | D26: 732872636 | E26: 20572159 | G26: 20572159
A27: 1104111 | B27: CLIENTES NACIONALES2 | C27: 386419703 | D27: 308133669 | E27: 78286034 | G27: 78286034
A28: 1104302 | B28: ANTICIPOS SUELDOS | C28: 17712932 | D28: 17831375 | F28: 118443 | H28: 118443
A29: 1104403 | B29: ANTICIPO PROVEEDORES | C29: 289899801 | D29: 205472533 | E29: 84427268 | G29: 84427268
A30: 1104404 | B30: ANTICIPO HONORARIOS | C30: 467500 | D30: 0 | E30: 467500 | G30: 467500
A31: 1104405 | B31: ANTICIPO AGENCIA DE ADUANAS | C31: 188187995 | D31: 176649982 | E31: 11538013 | G31: 11538013
A32: 1106401 | B32: EXISTENCIAS NACIONALES | C32: 1809970170 | D32: 723742759 | E32: 1086227411 | G32: 1086227411
A33: 1106802 | B33: MERCADERIA EN TRANSITO USD | C33: 960946062 | D33: 888556009 | E33: 72390053 | G33: 72390053
A34: 1109101 | B34: IVA CREDITO FISCAL (COMPRAS) | C34: 1376913922 | D34: 1376913922
A35: 1109103 | B35: REMANENTE IVA CREDITO FISCAL | C35: 156091273 | D35: 45133504 | E35: 110957769 | G35: 110957769
A36: 1202101 | B36: GARANTIAS DE ARRIENDO | C36: 113180701 | D36: 12385031 | E36: 100795670 | G36: 100795670
A37: 1209401 | B37: MUEBLES, UTILES Y OTROS | C37: 320748277 | D37: 0 | E37: 320748277 | G37: 320748277
A38: 1209402 | B38: EQUIPOS COMPUTACIONALES | C38: 46302483 | D38: 0 | E38: 46302483 | G38: 46302483
A39: 1209904 | B39: DEPRECIACION ACUMULADA MUEBLES Y UTILES | C39: 0 | D39: 39334629 | F39: 39334629 | H39: 39334629
A40: 1209905 | B40: DEPRECIACION ACUMULADA EQUIPOS COMPUTACIONALES | C40: 0 | D40: 5034293 | F40: 5034293 | H40: 5034293
A41: 2101203 | B41: PRESTAMOS NO BANCARIOS MONTO A PAGAR U$S | C41: 54955117 | D41: 562835235 | F41: 507880118 | H41: 507880118
A42: 2101601 | B42: TARJETA CREDITO CLP | C42: 3086725 | D42: 3304031 | F42: 217306 | H42: 217306
A43: 2102102 | B43: PROVEEDORES US$ | C43: 3485517634 | D43: 6162706424 | F43: 2677188790 | H43: 2677188790
A44: 2102103 | B44: PROVEEDORES $ | C44: 1090055747 | D44: 1232236133 | F44: 142180386 | H44: 142180386
A45: 2102401 | B45: HONORARIOS POR PAGAR | C45: 15592823 | D45: 16680785 | F45: 1087962 | H45: 1087962
...

Sheet Planilla Compras unificada
A1: Nro | B1: Tipo Doc | C1: Tipo Compra | D1: RUT Proveedor | E1: Razon Social | F1: Folio | G1: Fecha Docto | H1: Monto Exento | I1: Monto Neto | J1: Monto IVA Recuperable | K1: Monto Iva No Recuperable | L1: Monto Total | M1: Glosa documento/descripcion gasto o servicio | N1: Numero cta Magnus | O1: Nombre Cuenta | P1: RESPALDO PDF
A2: 1 | B2: 33 | C2: Del Giro | D2: 96851800-3 | E2: Asesores en Viaje S.A. | F2: 230611 | G2: 45252 | H2: 615760 | I2: 17900 | J2: 3401 | L2: 637061 | M2: Servicios de Viaje y/o turismo. Referencia:; EXPEDIENTE: 3002-23005155; SALIDA: 25.11.2023 RUTA: EZE-SCL-EZE PASAJERO: PINTO,GABRIEL ALEJANDRO(IDAAC273778); Nro. TKT: 30537549184 VALOR TKT VIA LA; SERVICIO DE AGENCIA: $ ; Servicios de Viaje y/o turismo. Referencia:; Servicios afectos incluidos en el detalle de servicios | N2: 8040703 | O2: GASTOS DE HOSPEDAJE Y VIAJES DE APOYO VENTA CLP | P2: Ø Documentado
A3: 2 | B3: 33 | C3: Del Giro | D3: 96851800-3 | E3: Asesores en Viaje S.A. | F3: 230612 | G3: 45252 | H3: 217485 | I3: 17900 | J3: 3401 | L3: 238786 | M3: Servicios de Viaje y/o turismo. Referencia:; EXPEDIENTE: 3002-23005156 - SALIDA: 02.12.2023 RUTA: SCL-AEP PASAJERO: FERNANDEZ SUAREZ,LEOPOLDO Nro. TKT: 30537549195 VALOR TKT VIA H2: $ 217.485 SERVICIO DE AGENCIA: $ 21.301; Servicios de Viaje y/o turismo. Referencia:; Servicios afectos incluidos en el detalle de servicios | N3: 8040703 | O3: GASTOS DE HOSPEDAJE Y VIAJES DE APOYO VENTA CLP | P3: Ø Documentado
A4: 3 | B4: 33 | C4: Del Giro | D4: 77190393-2 | E4: EASY POINT LOGISTICS SPA | F4: 952 | G4: 45253 | H4: 0 | I4: 219179 | J4: 41644 | L4: 260823 | M4: GESTION DE IMPORTACION SHIP031 | N4: 1060603 | O4: MATERIALES CLP | P4: Ø Documentado
A5: 4 | B5: 33 | C5: Del Giro | D5: 77450082-0 | E5: GRUPO MONTECARLO SPA | F5: 96 | G5: 45257 | H5: 0 | I5: 67227 | J5: 12773 | L5: 80000 | M5: CARGA COMBUSTIBLE | N5: 8050605 | O5: OTROS ARRIENDOS CLP | P5: Ø Documentado
A6: 5 | B6: 33 | C6: Del Giro | D6: 83628100-4 | E6: SONDA S.A. | F6: 343259 | G6: 45259 | H6: 0 | I6: 202813239 | J6: 38534515 | L6: 241347754 | M6: Facturación por 60% final del Negocio; US5 231927.04 T/C 874.47 al 29-11-2023 | N6: 8050803 | O6: SERVICIO DE SOPORTE DE SISTEMAS CLP | P6: Ø Documentado
A7: 6 | B7: 34 | C7: Del Giro | D7: 77716312-4 | E7: RSM CHILE CONTABILIDAD Y PROCESOS LIMITADA | F7: 1331 | G7: 45261 | H7: 1043472 | I7: 0 | J7: 0 | L7: 1043472 | M7: Servicios de contabilidad USD 200 a T/C 869.56; Cumplimiento tributario USD 200 a T/C 869.56; Otros servicios BPO USD 500 a T/C 869.56; | N7: 8050501 | O7: HONORARIOS PROFESIONALES CLP | P7: Ø Documentado
A8: 7 | B8: 33 | C8: Del Giro | D8: 81201000-K | E8: CENCOSUD RETAIL S.A. | F8: 19897331 | G8: 45261 | H8: 0 | I8: 19080 | J8: 3626 | L8: 24416 | M8: - | N8: 8040402 | O8: OTROS GASTOS VENTA CLP | P8: Օ Sin Documento
A9: 8 | B9: 33 | C9: Del Giro | D9: 81201000-K | E9: CENCOSUD RETAIL S.A. | F9: 19897339 | G9: 45263 | H9: 0 | I9: 79934 | J9: 15188 | L9: 97430 | M9: - | N9: 8040402 | O9: OTROS GASTOS VENTA CLP | P9: Օ Sin Documento
A10: 9 | B10: 33 | C10: Del Giro | D10: 97023000-9 | E10: Banco ItaÃº Chile | F10: 6413164 | G10: 45267 | H10: 0 | I10: 731 | J10: 139 | L10: 870 | M10: - | N10: 8051301 | O10: GASTOS BANCARIOS CLP | P10: Օ Sin Documento
A11: 10 | B11: 34 | C11: Del Giro | D11: 97023000-9 | E11: Banco ItaÃº Chile | F11: 1805946 | G11: 45267 | H11: 0 | I11: 0 | J11: 0 | L11: 0 | M11: - | N11: 8051301 | O11: GASTOS BANCARIOS CLP | P11: Օ Sin Documento
A12: 11 | B12: 33 | C12: Del Giro | D12: 81201000-K | E12: CENCOSUD RETAIL S.A. | F12: 19897358 | G12: 45268 | H12: 0 | I12: 17634 | J12: 3350 | L12: 22025 | M12: - | N12: 8040402 | O12: OTROS GASTOS VENTA CLP | P12: Օ Sin Documento
A13: 12 | B13: 34 | C13: Del Giro | D13: 76079405-8 | E13: PESCO CAPACITACIONES LIMITADA | F13: 3442 | G13: 45271 | H13: 704000 | I13: 0 | J13: 0 | L13: 704000 | M13: Capacitacion de primeros auxilios , RCP, manejo del trauma | N13: 8050112 | O13: GASTOS DE CAPACITACION - ADM CLP | P13: Ø Documentado
... A26: 25 | B26: 34 | C26: Del Giro | D26: 97023000-9 | E26: Banco ItaÃº Chile | F26: 2028745 | G26: 45289 | H26: 0 | I26: 0 | J26: 0 | L26: 0 | M26: - | N26: 8051301 | O26: GASTOS BANCARIOS CLP | P26: Օ Sin Documento

Sheet 01-31
A1: Nro | B1: Tipo Doc | C1: Tipo Compra | D1: RUT Proveedor | E1: Razon Social | F1: Folio | G1: Fecha Docto | H1: Monto Exento | I1: Monto Neto | J1: Monto IVA Recuperable | K1: Monto Iva No Recuperable | L1: Monto Total | M1: Glosa documento/descripcion gasto o servicio | N1: Numero cta Magnus | O1: Nombre Cuenta | P1: RESPALDO PDF | Q1: Ø Documentado | R1: Օ Sin Documento
A2: 1 | B2: 33 | C2: Del Giro | D2: 96851800-3 | E2: Asesores en Viaje S.A. | F2: 230611 | G2: 45252 | H2: 615760 | I2: 17900 | J2: 3401 | L2: 637061 | M2: Servicios de Viaje y/o turismo. Referencia:; EXPEDIENTE: 3002-23005155; SALIDA: 25.11.2023 RUTA: EZE-SCL-EZE PASAJERO: PINTO,GABRIEL ALEJANDRO(IDAAC273778); Nro. TKT: 30537549184 VALOR TKT VIA LA; SERVICIO DE AGENCIA: $ ; Servicios de Viaje y/o turismo. Referencia:; Servicios afectos incluidos en el detalle de servicios | N2: 8040703 | O2: GASTOS DE HOSPEDAJE Y VIAJES DE APOYO VENTA CLP | P2: Ø Documentado
A3: 2 | B3: 33 | C3: Del Giro | D3: 96851800-3 | E3: Asesores en Viaje S.A. | F3: 230612 | G3: 45252 | H3: 217485 | I3: 17900 | J3: 3401 | L3: 238786 | M3: Servicios de Viaje y/o turismo. Referencia:; EXPEDIENTE: 3002-23005156 - SALIDA: 02.12.2023 RUTA: SCL-AEP PASAJERO: FERNANDEZ SUAREZ,LEOPOLDO Nro. TKT: 30537549195 VALOR TKT VIA H2: $ 217.485 SERVICIO DE AGENCIA: $ 21.301; Servicios de Viaje y/o turismo. Referencia:; Servicios afectos incluidos en el detalle de servicios | N3: 8040703 | O3: GASTOS DE HOSPEDAJE Y VIAJES DE APOYO VENTA CLP | P3: Ø Documentado
A4: 3 | B4: 33 | C4: Del Giro | D4: 77190393-2 | E4: EASY POINT LOGISTICS SPA | F4: 952 | G4: 45253 | H4: 0 | I4: 219179 | J4: 41644 | L4: 260823 | M4: GESTION DE IMPORTACION SHIP031 | N4: 1060603 | O4: MATERIALES CLP | P4: Ø Documentado
A5: 4 | B5: 33 | C5: Del Giro | D5: 77450082-0 | E5: GRUPO MONTECARLO SPA | F5: 96 | G5: 45257 | H5: 0 | I5: 67227 | J5: 12773 | L5: 80000 | M5: CARGA COMBUSTIBLE | N5: 8050605 | O5: OTROS ARRIENDOS CLP | P5: Ø Documentado
A6: 5 | B6: 33 | C6: Del Giro | D6: 83628100-4 | E6: SONDA S.A. | F6: 343259 | G6: 45259 | H6: 0 | I6: 202813239 | J6: 38534515 | L6: 241347754 | M6: Facturación por 60% final del Negocio; US5 231927.04 T/C 874.47 al 29-11-2023 | N6: 8050803 | O6: SERVICIO DE SOPORTE DE SISTEMAS CLP | P6: Ø Documentado
A7: 6 | B7: 34 | C7: Del Giro | D7: 77716312-4 | E7: RSM CHILE CONTABILIDAD Y PROCESOS LIMITADA | F7: 1331 | G7: 45261 | H7: 1043472 | I7: 0 | J7: 0 | L7: 1043472 | M7: Servicios de contabilidad USD 200 a T/C 869.56; Cumplimiento tributario USD 200 a T/C 869.56; Otros servicios BPO USD 500 a T/C 869.56; | N7: 8050501 | O7: HONORARIOS PROFESIONALES CLP | P7: Ø Documentado
A8: 7 | B8: 33 | C8: Del Giro | D8: 81201000-K | E8: CENCOSUD RETAIL S.A. | F8: 19897331 | G8: 45261 | H8: 0 | I8: 19080 | J8: 3626 | L8: 24416 | M8: - | N8: 8040402 | O8: OTROS GASTOS VENTA CLP | P8: Օ Sin Documento
A9: 8 | B9: 33 | C9: Del Giro | D9: 81201000-K | E9: CENCOSUD RETAIL S.A. | F9: 19897339 | G9: 45263 | H9: 0 | I9: 79934 | J9: 15188 | L9: 97430 | M9: - | N9: 8040402 | O9: OTROS GASTOS VENTA CLP | P9: Օ Sin Documento
A10: 9 | B10: 33 | C10: Del Giro | D10: 97023000-9 | E10: Banco ItaÃº Chile | F10: 6413164 | G10: 45267 | H10: 0 | I10: 731 | J10: 139 | L10: 870 | M10: - | N10: 8051301 | O10: GASTOS BANCARIOS CLP | P10: Օ Sin Documento
A11: 10 | B11: 34 | C11: Del Giro | D11: 97023000-9 | E11: Banco ItaÃº Chile | F11: 1805946 | G11: 45267 | H11: 0 | I11: 0 | J11: 0 | L11: 0 | M11: - | N11: 8051301 | O11: GASTOS BANCARIOS CLP | P11: Օ Sin Documento
A12: 11 | B12: 33 | C12: Del Giro | D12: 81201000-K | E12: CENCOSUD RETAIL S.A. | F12: 19897358 | G12: 45268 | H12: 0 | I12: 17634 | J12: 3350 | L12: 22025 | M12: - | N12: 8040402 | O12: OTROS GASTOS VENTA CLP | P12: Օ Sin Documento
A13: 12 | B13: 34 | C13: Del Giro | D13: 76079405-8 | E13: PESCO CAPACITACIONES LIMITADA | F13: 3442 | G13: 45271 | H13: 704000 | I13: 0 | J13: 0 | L13: 704000 | M13: Capacitacion de primeros auxilios , RCP, manejo del trauma | N13: 8050112 | O13: GASTOS DE CAPACITACION - ADM CLP | P13: Ø Documentado
... A26: 25 | B26: 34 | C26: Del Giro | D26: 97023000-9 | E26: Banco ItaÃº Chile | F26: 2028745 | G26: 45289 | H26: 0 | I26: 0 | J26: 0 | L26: 0 | M26: - | N26: 8051301 | O26: GASTOS BANCARIOS CLP | P26: Օ Sin Documento

Sheet ASIGNACION
A1: Nro | B1: Tipo Doc | C1: Tipo Compra | D1: RUT Proveedor | E1: Razon Social | F1: Folio | G1: Fecha Docto | H1: Monto Exento | I1: Monto Neto | J1: Monto IVA Recuperable | K1: Monto Iva No Recuperable | L1: Monto Total | M1: Glosa documento/descripcion gasto o servicio | N1: Numero cta Magnus | O1: Nombre Cuenta | P1: RESPALDO PDF
A2: 1 | B2: 33 | C2: Del Giro | D2: 96851800-3 | E2: Asesores en Viaje S.A. | F2: 230611 | G2: 45252 | H2: 615760 | I2: 17900 | J2: 3401 | L2: 637061 | M2: - | N2: =VLOOKUP(D2,Titulares!$A$2:$F$323,5,) -> 8040703 | O2: =VLOOKUP(N2,Titulares!$E$2:$F$323,2,) -> GASTOS DE HOSPEDAJE Y VIAJES DE APOYO VENTA CLP | Q2: Ø Documentado
A3: 2 | B3: 33 | C3: Del Giro | D3: 96851800-3 | E3: Asesores en Viaje S.A. | F3: 230612 | G3: 45252 | H3: 217485 | I3: 17900 | J3: 3401 | L3: 238786 | M3: - | N3: =VLOOKUP(D3,Titulares!$A$2:$F$323,5,) -> 8040703 | O3: =VLOOKUP(N3,Titulares!$E$2:$F$323,2,) -> GASTOS DE HOSPEDAJE Y VIAJES DE APOYO VENTA CLP | Q3: Օ Sin Documento
A4: 3 | B4: 33 | C4: Del Giro | D4: 77190393-2 | E4: EASY POINT LOGISTICS SPA | F4: 952 | G4: 45253 | H4: 0 | I4: 219179 | J4: 41644 | L4: 260823 | M4: - | N4: =VLOOKUP(D4,Titulares!$A$2:$F$323,5,) -> 1060603 | O4: =VLOOKUP(N4,Titulares!$E$2:$F$323,2,) -> MATERIALES CLP
A5: 4 | B5: 33 | C5: Del Giro | D5: 77450082-0 | E5: GRUPO MONTECARLO SPA | F5: 96 | G5: 45257 | H5: 0 | I5: 67227 | J5: 12773 | L5: 80000 | M5: - | N5: =VLOOKUP(D5,Titulares!$A$2:$F$323,5,) -> 8050605 | O5: =VLOOKUP(N5,Titulares!$E$2:$F$323,2,) -> OTROS ARRIENDOS CLP
A6: 5 | B6: 33 | C6: Del Giro | D6: 83628100-4 | E6: SONDA S.A. | F6: 343259 | G6: 45259 | H6: 0 | I6: 202813239 | J6: 38534515 | L6: 241347754 | M6: - | N6: =VLOOKUP(D6,Titulares!$A$2:$F$323,5,) -> 8050803 | O6: =VLOOKUP(N6,Titulares!$E$2:$F$323,2,) -> SERVICIO DE SOPORTE DE SISTEMAS CLP
A7: 21 | B7: 34 | C7: Del Giro | D7: 77716312-4 | E7: RSM CHILE CONTABILIDAD Y PROCESOS LIMITADA | F7: 1331 | G7: 45261 | H7: 1043472 | I7: 0 | J7: 0 | L7: 1043472 | M7: - | N7: =VLOOKUP(D7,Titulares!$A$2:$F$323,5,) -> 8050501 | O7: =VLOOKUP(N7,Titulares!$E$2:$F$323,2,) -> HONORARIOS PROFESIONALES CLP
A8: 6 | B8: 33 | C8: Del Giro | D8: 81201000-K | E8: CENCOSUD RETAIL S.A. | F8: 19897331 | G8: 45261 | H8: 0 | I8: 19080 | J8: 3626 | L8: 24416 | M8: - | N8: =VLOOKUP(D8,Titulares!$A$2:$F$323,5,) -> 8040402 | O8: =VLOOKUP(N8,Titulares!$E$2:$F$323,2,) -> OTROS GASTOS VENTA CLP
A9: 7 | B9: 33 | C9: Del Giro | D9: 81201000-K | E9: CENCOSUD RETAIL S.A. | F9: 19897339 | G9: 45263 | H9: 0 | I9: 79934 | J9: 15188 | L9: 97430 | M9: - | N9: =VLOOKUP(D9,Titulares!$A$2:$F$323,5,) -> 8040402 | O9: =VLOOKUP(N9,Titulares!$E$2:$F$323,2,) -> OTROS GASTOS VENTA CLP
A10: 8 | B10: 33 | C10: Del Giro | D10: 97023000-9 | E10: Banco ItaÃº Chile | F10: 6413164 | G10: 45267 | H10: 0 | I10: 731 | J10: 139 | L10: 870 | M10: - | N10: =VLOOKUP(D10,Titulares!$A$2:$F$323,5,) -> 8051301 | O10: =VLOOKUP(N10,Titulares!$E$2:$F$323,2,) -> GASTOS BANCARIOS CLP
A11: 22 | B11: 34 | C11: Del Giro | D11: 97023000-9 | E11: Banco ItaÃº Chile | F11: 1805946 | G11: 45267 | H11: 0 | I11: 0 | J11: 0 | L11: 0 | M11: - | N11: =VLOOKUP(D11,Titulares!$A$2:$F$323,5,) -> 8051301 | O11: =VLOOKUP(N11,Titulares!$E$2:$F$323,2,) -> GASTOS BANCARIOS CLP
A12: 9 | B12: 33 | C12: Del Giro | D12: 81201000-K | E12: CENCOSUD RETAIL S.A. | F12: 19897358 | G12: 45268 | H12: 0 | I12: 17634 | J12: 3350 | L12: 22025 | M12: - | N12: =VLOOKUP(D12,Titulares!$A$2:$F$323,5,) -> 8040402 | O12: =VLOOKUP(N12,Titulares!$E$2:$F$323,2,) -> OTROS GASTOS VENTA CLP
A13: 23 | B13: 34 | C13: Del Giro | D13: 76079405-8 | E13: PESCO CAPACITACIONES LIMITADA | F13: 3442 | G13: 45271 | H13: 704000 | I13: 0 | J13: 0 | L13: 704000 | M13: - | N13: =VLOOKUP(D13,Titulares!$A$2:$F$323,5,) -> 8050112 | O13: =VLOOKUP(N13,Titulares!$E$2:$F$323,2,) -> GASTOS DE CAPACITACION - ADM CLP
A14: 10 | B14: 33 | C14: Del Giro | D14: 97023000-9 | E14: Banco ItaÃº Chile | F14: 6426323 | G14: 45271 | H14: 0 | I14: 91422 | J14: 17370 | L14: 108792 | M14: - | N14: =VLOOKUP(D14,Titulares!$A$2:$F$323,5,) -> 8051301 | O14: =VLOOKUP(N14,Titulares!$E$2:$F$323,2,) -> GASTOS BANCARIOS CLP
A15: 11 | B15: 33 | C15: Del Giro | D15: 97023000-9 | E15: Banco ItaÃº Chile | F15: 6432905 | G15: 45273 | H15: 0 | I15: 96868 | J15: 18405 | L15: 115273 | M15: - | N15: =VLOOKUP(D15,Titulares!$A$2:$F$323,5,) -> 8051301 | O15: =VLOOKUP(N15,Titulares!$E$2:$F$323,2,) -> GASTOS BANCARIOS CLP
... A26: 25 | B26: 34 | C26: Del Giro | D26: 97023000-9 | E26: Banco ItaÃº Chile | F26: 2028745 | G26: 45289 | H26: 0 | I26: 0 | J26: 0 | L26: 0 | M26: - | N26: =VLOOKUP(D26,Titulares!$A$2:$F$323,5,) -> 8051301 | O26: =VLOOKUP(N26,Titulares!$E$2:$F$323,2,) -> GASTOS BANCARIOS CLP
N27: =VLOOKUP(D27,Titulares!$A$2:$F$323,5,) -> #N/A | O27: =VLOOKUP(N27,Titulares!$E$2:$F$323,2,) -> #N/A
N28: =VLOOKUP(D28,Titulares!$A$2:$F$323,5,) -> #N/A | O28: =VLOOKUP(N28,Titulares!$E$2:$F$323,2,) -> #N/A
N29: =VLOOKUP(D29,Titulares!$A$2:$F$323,5,) -> #N/A | O29: =VLOOKUP(N29,Titulares!$E$2:$F$323,2,) -> #N/A
N30: =VLOOKUP(D30,Titulares!$A$2:$F$323,5,) -> #N/A | O30: =VLOOKUP(N30,Titulares!$E$2:$F$323,2,) -> #N/A
N31: =VLOOKUP(D31,Titulares!$A$2:$F$323,5,) -> #N/A | O31: =VLOOKUP(N31,Titulares!$E$2:$F$323,2,) -> #N/A
N32: =VLOOKUP(D32,Titulares!$A$2:$F$323,5,) -> #N/A | O32: =VLOOKUP(N32,Titulares!$E$2:$F$323,2,) -> #N/A
N33: =VLOOKUP(D33,Titulares!$A$2:$F$323,5,) -> #N/A | O33: =VLOOKUP(N33,Titulares!$E$2:$F$323,2,) -> #N/A
N34: =VLOOKUP(D34,Titulares!$A$2:$F$323,5,) -> #N/A | O34: =VLOOKUP(N34,Titulares!$E$2:$F$323,2,) -> #N/A
N35: =VLOOKUP(D35,Titulares!$A$2:$F$323,5,) -> #N/A | O35: =VLOOKUP(N35,Titulares!$E$2:$F$323,2,) -> #N/A
N36: =VLOOKUP(D36,Titulares!$A$2:$F$323,5,) -> #N/A | O36: =VLOOKUP(N36,Titulares!$E$2:$F$323,2,) -> #N/A
N37: =VLOOKUP(D37,Titulares!$A$2:$F$323,5,) -> #N/A | O37: =VLOOKUP(N37,Titulares!$E$2:$F$323,2,) -> #N/A
N38: =VLOOKUP(D38,Titulares!$A$2:$F$323,5,) -> #N/A | O38: =VLOOKUP(N38,Titulares!$E$2:$F$323,2,) -> #N/A
... N55: =VLOOKUP(D55,Titulares!$A$2:$F$323,5,) -> #N/A | O55: =VLOOKUP(N55,Titulares!$E$2:$F$323,2,) -> #N/A

Sheet Titulares
A1: Titular | B1: Nombre Titular | C1: Tipo Doc | D1: Nro Doc | E1: NUMERO CTA | F1: GASTO
A2: 97023000-9 | B2: Banco ItaÃº Chile | C2: RUT | D2: 97023000-9 | E2: 8051301 | F2: GASTOS BANCARIOS CLP
A3: 77190393-2 | B3: EASY POINT LOGISTICS SPA | C3: RUT | D3: 77190393-2 | E3: 1060603 | F3: MATERIALES CLP
A4: 96631520-2 | B4: FastAir Almacenes de Carga S.A. | C4: RUT | D4: 96631520-2 | E4: 1060603 | F4: MATERIALES CLP
A5: 77450082-0 | B5: GRUPO MONTECARLO SPA | C5: RUT | D5: 77450082-0 | E5: 8050605 | F5: OTROS ARRIENDOS CLP
A6: 5391000-9 | B6: MARINA PATRICIA MOYA VARAS | C6: RUT | D6: 5391000-9 | E6: 1060603 | F6: MATERIALES CLP
A7: 6554967-0 | B7: MARIO HUMBERTO ARANEDA MEZA | C7: RUT | D7: 6554967-0 | E7: 1060603 | F7: MATERIALES CLP
A8: 76162740-6 | B8: RITTAL LIMITADA | C8: RUT | D8: 76162740-6 | E8: 8040402 | F8: OTROS GASTOS VENTA CLP
A9: 77716312-4 | B9: RSM CHILE CONTABILIDAD Y PROCESOS LIMITADA | C9: RUT | D9: 77716312-4 | E9: 8050501 | F9: HONORARIOS PROFESIONALES CLP
A10: 94058000-5 | B10: SERVICIOS AEROPORTUARIOS AEROSAN SA | C10: RUT | D10: 94058000-5 | E10: 1060603 | F10: MATERIALES CLP
A11: 76320613-0 | B11: TIBA CHILE SPA | C11: RUT | D11: 76320613-0 | E11: 1060603 | F11: MATERIALES CLP
A12: 78953470-5 | B12: United Parcel Service de Chile Limitada | C12: RUT | D12: 78953470-5 | E12: 1060603 | F12: MATERIALES CLP
A13: 76696743-4 | B13: Synixtor Chile Spa | C13: RUT | D13: 76696743-4 | E13: 8040402 | F13: OTROS GASTOS VENTA CLP
... A28: 76079405-8 | B28: PESCO CAPACITACIONES LIMITADA | C28: RUT | D28: 76079405-8 | E28: 8050112 | F28: GASTOS DE CAPACITACION - ADM CLP

Sheet 31.12.2023
A1: Nro | B1: Tipo Doc | C1: Tipo Compra | D1: RUT Proveedor | E1: Razon Social | F1: Folio | G1: Fecha Docto | H1: Fecha Recepcion | I1: Fecha Acuse | J1: Monto Exento | K1: Monto Neto | L1: Monto IVA Recuperable | M1: Monto Iva No Recuperable | N1: Codigo IVA No Rec. | O1: Monto Total | P1: Monto Neto Activo Fijo | Q1: IVA Activo Fijo | R1: IVA uso Comun | S1: Impto. Sin Derecho a Credito | T1: IVA No Retenido | U1: Tabacos Puros | V1: Tabacos Cigarrillos | W1: Tabacos Elaborados | X1: NCE o NDE sobre Fact. de Compra | Y1: Codigo Otro Impuesto | Z1: Valor Otro Impuesto | AA1: Tasa Otro Impuesto
A2: 1 | B2: 33 | C2: Del Giro | D2: 96851800-3 | E2: Asesores en Viaje S.A. | F2: 230611 | G2: 45252 | H2: 45252.72 | J2: 615760 | K2: 17900 | L2: 3401 | O2: 637061 | T2: 0 | X2: 0
A3: 2 | B3: 33 | C3: Del Giro | D3: 96851800-3 | E3: Asesores en Viaje S.A. | F3: 230612 | G3: 45252 | H3: 45252.72 | J3: 217485 | K3: 17900 | L3: 3401 | O3: 238786 | T3: 0 | X3: 0
A4: 3 | B4: 33 | C4: Del Giro | D4: 77190393-2 | E4: EASY POINT LOGISTICS SPA | F4: 952 | G4: 45253 | H4: 45253.539 | J4: 0 | K4: 219179 | L4: 41644 | O4: 260823 | T4: 0 | X4: 0
A5: 4 | B5: 33 | C5: Del Giro | D5: 77450082-0 | E5: GRUPO MONTECARLO SPA | F5: 96 | G5: 45257 | H5: 45257.92 | J5: 0 | K5: 67227 | L5: 12773 | O5: 80000 | T5: 0 | X5: 0
A6: 5 | B6: 33 | C6: Del Giro | D6: 83628100-4 | E6: SONDA S.A. | F6: 343259 | G6: 45259 | H6: 45259.707 | J6: 0 | K6: 202813239 | L6: 38534515 | O6: 241347754 | T6: 0 | X6: 0
A7: 21 | B7: 34 | C7: Del Giro | D7: 77716312-4 | E7: RSM CHILE CONTABILIDAD Y PROCESOS LIMITADA | F7: 1331 | G7: 45261 | H7: 45261.632 | J7: 1043472 | K7: 0 | L7: 0 | O7: 1043472 | T7: 0 | X7: 0
A8: 6 | B8: 33 | C8: Del Giro | D8: 81201000-K | E8: CENCOSUD RETAIL S.A. | F8: 19897331 | G8: 45261 | H8: 45261.892 | J8: 0 | K8: 19080 | L8: 3626 | O8: 24416 | T8: 0 | X8: 0 | Y8: 271 | Z8: 1710 | AA8: 18
A9: 7 | B9: 33 | C9: Del Giro | D9: 81201000-K | E9: CENCOSUD RETAIL S.A. | F9: 19897339 | G9: 45263 | H9: 45263.691 | J9: 0 | K9: 79934 | L9: 15188 | O9: 97430 | T9: 0 | X9: 0 | Y9: 271 | Z9: 1971 | AA9: 18
A10: 8 | B10: 33 | C10: Del Giro | D10: 97023000-9 | E10: Banco ItaÃº Chile | F10: 6413164 | G10: 45267 | H10: 45267.465 | J10: 0 | K10: 731 | L10: 139 | O10: 870 | T10: 0 | X10: 0
A11: 22 | B11: 34 | C11: Del Giro | D11: 97023000-9 | E11: Banco ItaÃº Chile | F11: 1805946 | G11: 45267 | H11: 45267.988 | J11: 0 | K11: 0 | L11: 0 | O11: 0 | T11: 0 | X11: 0
A12: 9 | B12: 33 | C12: Del Giro | D12: 81201000-K | E12: CENCOSUD RETAIL S.A. | F12: 19897358 | G12: 45268 | H12: 45268.71 | J12: 0 | K12: 17634 | L12: 3350 | O12: 22025 | T12: 0 | X12: 0 | Y12: 271 | Z12: 1041 | AA12: 18
A13: 23 | B13: 34 | C13: Del Giro | D13: 76079405-8 | E13: PESCO CAPACITACIONES LIMITADA | F13: 3442 | G13: 45271 | H13: 45271.477 | J13: 704000 | K13: 0 | L13: 0 | O13: 704000 | T13: 0 | X13: 0
A14: 10 | B14: 33 | C14: Del Giro | D14: 97023000-9 | E14: Banco ItaÃº Chile | F14: 6426323 | G14: 45271 | H14: 45272.626 | J14: 0 | K14: 91422 | L14: 17370 | O14: 108792 | T14: 0 | X14: 0
A15: 11 | B15: 33 | C15: Del Giro | D15: 97023000-9 | E15: Banco ItaÃº Chile | F15: 6432905 | G15: 45273 | H15: 45274.592 | J15: 0 | K15: 96868 | L15: 18405 | O15: 115273 | T15: 0 | X15: 0
A16: 12 | B16: 33 | C16: Del Giro | D16: 77450082-0 | E16: GRUPO MONTECARLO SPA | F16: 99 | G16: 45274 | H16: 45274.981 | J16: 0 | K16: 57000 | L16: 10830 | O16: 67830 | T16: 0 | X16: 0
A17: 13 | B17: 33 | C17: Del Giro | D17: 78953470-5 | E17: United Parcel Service de Chile Limitada | F17: 991115 | G17: 45279 | H17: 45279.195 | J17: 0 | K17: 40517 | L17: 7698 | O17: 48215 | T17: 0 | X17: 0
A18: 14 | B18: 33 | C18: Del Giro | D18: 96841630-8 | E18: KOLFF S.P.A | F18: 128038 | G18: 45279 | H18: 45279.559 | J18: 0 | K18: 6981311 | L18: 1326449 | O18: 8307760 | T18: 0 | X18: 0
A19: 15 | B19: 33 | C19: Del Giro | D19: 96841630-8 | E19: KOLFF S.P.A | F19: 128039 | G19: 45279 | H19: 45279.56 | J19: 0 | K19: 6512813 | L19: 1237434 | O19: 7750247 | T19: 0 | X19: 0
A20: 16 | B20: 33 | C20: Del Giro | D20: 96841630-8 | E20: KOLFF S.P.A | F20: 128040 | G20: 45279 | H20: 45279.562 | J20: 0 | K20: 3281032 | L20: 623396 | O20: 3904428 | T20: 0 | X20: 0
A21: 17 | B21: 33 | C21: Del Giro | D21: 96841630-8 | E21: KOLFF S.P.A | F21: 128043 | G21: 45279 | H21: 45279.564 | J21: 0 | K21: 1540927 | L21: 292776 | O21: 1833703 | T21: 0 | X21: 0
A22: 18 | B22: 33 | C22: Del Giro | D22: 97023000-9 | E22: Banco ItaÃº Chile | F22: 6441008 | G22: 45281 | H22: 45282.437 | J22: 0 | K22: 95565 | L22: 18157 | O22: 113722 | T22: 0 | X22: 0
A23: 19 | B23: 33 | C23: Del Giro | D23: 77190393-2 | E23: EASY POINT LOGISTICS SPA | F23: 1031 | G23: 45282 | H23: 45282.595 | J23: 0 | K23: 220290 | L23: 41855 | O23: 262145 | T23: 0 | X23: 0
A24: 24 | B24: 34 | C24: Del Giro | D24: 97023000-9 | E24: Banco ItaÃº Chile | F24: 2026362 | G24: 45288 | H24: 45288.992 | J24: 0 | K24: 0 | L24: 0 | O24: 0 | T24: 0 | X24: 0
... A26: 25 | B26: 34 | C26: Del Giro | D26: 97023000-9 | E26: Banco ItaÃº Chile | F26: 2028745 | G26: 45289 | H26: 45289.986 | J26: 0 | K26: 0 | L26: 0 | O26: 0 | T26: 0 | X26: 0
A27: 26 | B27: 914 | C27: Del Giro | D27: 60805000-0 | E27: TESORERIA GENREAL DE LA REPLUBLICA | F27: 402029597 | G27: 45278 | H27: 45300.959 | J27: 0 | K27: 275439 | L27: 52333 | O27: 327772 | X27: 0

Sheet MAGNUS
F2: RUTA DE CARGA MASIVA DE COMPRAS

Sheet Cuentas
A1: 772612800 | B1: 1106401 | C1: 0 | D1: 0 | E1: EXISTENCIAS NACIONALES
A2: 768198470 | B2: 1209401 | C2: 0 | D2: 0 | E2: MUEBLES, UTILES Y OTROS
A3: 761721143 | B3: 3102102 | C3: 0 | D3: 0 | E3: COSTOS OPERATIVOS FLETES INTERNOS
A4: 773982201 | B4: 3102104 | C4: 0 | D4: 0 | E4: COMISIÓN CANAL DIGITAL
A5: 967564303 | B5: 3102105 | C5: 0 | D5: 0 | E5: FLETES CANAL DIGITAL
A6: 776458252 | B6: 3102108 | C6: 0 | D6: 0 | E6: SERVICIOS CANAL DIGITAL
A7: 833827006 | B7: 3102108 | C7: 0 | D7: 0 | E7: SERVICIOS CANAL DIGITAL
A8: 969089700 | B8: 3102113 | C8: 0 | D8: 0 | E8: LOGISTICA INTERNACION
A9: 181111186 | B9: 3105116 | C9: 0 | D9: 0 | E9: UNIFORMES
A10: 776008206 | B10: 3105201 | C10: 0 | D10: 0 | E10: HONORARIOS PROFESIONALES
A11: 777163124 | B11: 3105206 | C11: 0 | D11: 0 | E11: ASESORIA CONTABLE
A12: 765642396 | B12: 3105209 | C12: 0 | D12: 0 | E12: HONORARIOS POR ASESORIAS INFORMATICAS
... A27: 768322481 | B27: 3105833 | C27: 0 | D27: 0 | E27: SUMINISTROS PUBLICIDAD Y MARKETING
